2023-11-02 14:44:59 ERROR Traceback (most recent call last):
  File "C:\Users\oltie\AppData\Local\Programs\Python\Python310\lib\site-packages\wandb\cli\cli.py", line 102, in wrapper
    return func(*args, **kwargs)
  File "C:\Users\oltie\AppData\Local\Programs\Python\Python310\lib\site-packages\wandb\cli\cli.py", line 246, in login
    wandb.login(relogin=relogin, key=key, anonymous=anon_mode, host=host, force=True)
  File "C:\Users\oltie\AppData\Local\Programs\Python\Python310\lib\site-packages\wandb\sdk\wandb_login.py", line 77, in login
    configured = _login(**kwargs)
  File "C:\Users\oltie\AppData\Local\Programs\Python\Python310\lib\site-packages\wandb\sdk\wandb_login.py", line 298, in _login
    wlogin.prompt_api_key()
  File "C:\Users\oltie\AppData\Local\Programs\Python\Python310\lib\site-packages\wandb\sdk\wandb_login.py", line 228, in prompt_api_key
    raise UsageError("api_key not configured (no-tty). call " + directive)
wandb.errors.UsageError: api_key not configured (no-tty). call wandb login [your_api_key]

2023-11-02 14:45:27 ERROR Traceback (most recent call last):
  File "C:\Users\oltie\AppData\Local\Programs\Python\Python310\lib\site-packages\wandb\cli\cli.py", line 102, in wrapper
    return func(*args, **kwargs)
  File "C:\Users\oltie\AppData\Local\Programs\Python\Python310\lib\site-packages\wandb\cli\cli.py", line 246, in login
    wandb.login(relogin=relogin, key=key, anonymous=anon_mode, host=host, force=True)
  File "C:\Users\oltie\AppData\Local\Programs\Python\Python310\lib\site-packages\wandb\sdk\wandb_login.py", line 77, in login
    configured = _login(**kwargs)
  File "C:\Users\oltie\AppData\Local\Programs\Python\Python310\lib\site-packages\wandb\sdk\wandb_login.py", line 298, in _login
    wlogin.prompt_api_key()
  File "C:\Users\oltie\AppData\Local\Programs\Python\Python310\lib\site-packages\wandb\sdk\wandb_login.py", line 228, in prompt_api_key
    raise UsageError("api_key not configured (no-tty). call " + directive)
wandb.errors.UsageError: api_key not configured (no-tty). call wandb login [your_api_key]

2023-11-02 15:55:33 ERROR Traceback (most recent call last):
  File "C:\Users\oltie\AppData\Local\Programs\Python\Python310\lib\site-packages\wandb\cli\cli.py", line 102, in wrapper
    return func(*args, **kwargs)
  File "C:\Users\oltie\AppData\Local\Programs\Python\Python310\lib\site-packages\wandb\cli\cli.py", line 246, in login
    wandb.login(relogin=relogin, key=key, anonymous=anon_mode, host=host, force=True)
  File "C:\Users\oltie\AppData\Local\Programs\Python\Python310\lib\site-packages\wandb\sdk\wandb_login.py", line 77, in login
    configured = _login(**kwargs)
  File "C:\Users\oltie\AppData\Local\Programs\Python\Python310\lib\site-packages\wandb\sdk\wandb_login.py", line 298, in _login
    wlogin.prompt_api_key()
  File "C:\Users\oltie\AppData\Local\Programs\Python\Python310\lib\site-packages\wandb\sdk\wandb_login.py", line 228, in prompt_api_key
    raise UsageError("api_key not configured (no-tty). call " + directive)
wandb.errors.UsageError: api_key not configured (no-tty). call wandb login [your_api_key]

2023-11-02 15:56:55 ERROR Traceback (most recent call last):
  File "C:\Users\oltie\AppData\Local\Programs\Python\Python310\lib\site-packages\wandb\cli\cli.py", line 102, in wrapper
    return func(*args, **kwargs)
  File "C:\Users\oltie\AppData\Local\Programs\Python\Python310\lib\site-packages\wandb\cli\cli.py", line 246, in login
    wandb.login(relogin=relogin, key=key, anonymous=anon_mode, host=host, force=True)
  File "C:\Users\oltie\AppData\Local\Programs\Python\Python310\lib\site-packages\wandb\sdk\wandb_login.py", line 77, in login
    configured = _login(**kwargs)
  File "C:\Users\oltie\AppData\Local\Programs\Python\Python310\lib\site-packages\wandb\sdk\wandb_login.py", line 298, in _login
    wlogin.prompt_api_key()
  File "C:\Users\oltie\AppData\Local\Programs\Python\Python310\lib\site-packages\wandb\sdk\wandb_login.py", line 228, in prompt_api_key
    raise UsageError("api_key not configured (no-tty). call " + directive)
wandb.errors.UsageError: api_key not configured (no-tty). call wandb login [your_api_key]

2023-11-02 16:06:44 ERROR Traceback (most recent call last):
  File "C:\Users\oltie\AppData\Local\Programs\Python\Python310\lib\site-packages\wandb\cli\cli.py", line 102, in wrapper
    return func(*args, **kwargs)
  File "C:\Users\oltie\AppData\Local\Programs\Python\Python310\lib\site-packages\wandb\cli\cli.py", line 246, in login
    wandb.login(relogin=relogin, key=key, anonymous=anon_mode, host=host, force=True)
  File "C:\Users\oltie\AppData\Local\Programs\Python\Python310\lib\site-packages\wandb\sdk\wandb_login.py", line 77, in login
    configured = _login(**kwargs)
  File "C:\Users\oltie\AppData\Local\Programs\Python\Python310\lib\site-packages\wandb\sdk\wandb_login.py", line 298, in _login
    wlogin.prompt_api_key()
  File "C:\Users\oltie\AppData\Local\Programs\Python\Python310\lib\site-packages\wandb\sdk\wandb_login.py", line 228, in prompt_api_key
    raise UsageError("api_key not configured (no-tty). call " + directive)
wandb.errors.UsageError: api_key not configured (no-tty). call wandb login [your_api_key]

2023-11-02 16:08:15 ERROR Traceback (most recent call last):
  File "C:\Users\oltie\AppData\Local\Programs\Python\Python310\lib\site-packages\wandb\cli\cli.py", line 102, in wrapper
    return func(*args, **kwargs)
  File "C:\Users\oltie\AppData\Local\Programs\Python\Python310\lib\site-packages\wandb\cli\cli.py", line 246, in login
    wandb.login(relogin=relogin, key=key, anonymous=anon_mode, host=host, force=True)
  File "C:\Users\oltie\AppData\Local\Programs\Python\Python310\lib\site-packages\wandb\sdk\wandb_login.py", line 77, in login
    configured = _login(**kwargs)
  File "C:\Users\oltie\AppData\Local\Programs\Python\Python310\lib\site-packages\wandb\sdk\wandb_login.py", line 298, in _login
    wlogin.prompt_api_key()
  File "C:\Users\oltie\AppData\Local\Programs\Python\Python310\lib\site-packages\wandb\sdk\wandb_login.py", line 228, in prompt_api_key
    raise UsageError("api_key not configured (no-tty). call " + directive)
wandb.errors.UsageError: api_key not configured (no-tty). call wandb login [your_api_key]

2023-11-02 16:15:21 ERROR Traceback (most recent call last):
  File "C:\Users\oltie\AppData\Local\Programs\Python\Python310\lib\site-packages\wandb\cli\cli.py", line 102, in wrapper
    return func(*args, **kwargs)
  File "C:\Users\oltie\AppData\Local\Programs\Python\Python310\lib\site-packages\wandb\cli\cli.py", line 246, in login
    wandb.login(relogin=relogin, key=key, anonymous=anon_mode, host=host, force=True)
  File "C:\Users\oltie\AppData\Local\Programs\Python\Python310\lib\site-packages\wandb\sdk\wandb_login.py", line 77, in login
    configured = _login(**kwargs)
  File "C:\Users\oltie\AppData\Local\Programs\Python\Python310\lib\site-packages\wandb\sdk\wandb_login.py", line 298, in _login
    wlogin.prompt_api_key()
  File "C:\Users\oltie\AppData\Local\Programs\Python\Python310\lib\site-packages\wandb\sdk\wandb_login.py", line 228, in prompt_api_key
    raise UsageError("api_key not configured (no-tty). call " + directive)
wandb.errors.UsageError: api_key not configured (no-tty). call wandb login [your_api_key]

2023-11-02 16:29:39 ERROR Traceback (most recent call last):
  File "C:\Users\oltie\AppData\Local\Programs\Python\Python310\lib\site-packages\wandb\cli\cli.py", line 102, in wrapper
    return func(*args, **kwargs)
  File "C:\Users\oltie\AppData\Local\Programs\Python\Python310\lib\site-packages\wandb\cli\cli.py", line 246, in login
    wandb.login(relogin=relogin, key=key, anonymous=anon_mode, host=host, force=True)
  File "C:\Users\oltie\AppData\Local\Programs\Python\Python310\lib\site-packages\wandb\sdk\wandb_login.py", line 77, in login
    configured = _login(**kwargs)
  File "C:\Users\oltie\AppData\Local\Programs\Python\Python310\lib\site-packages\wandb\sdk\wandb_login.py", line 298, in _login
    wlogin.prompt_api_key()
  File "C:\Users\oltie\AppData\Local\Programs\Python\Python310\lib\site-packages\wandb\sdk\wandb_login.py", line 228, in prompt_api_key
    raise UsageError("api_key not configured (no-tty). call " + directive)
wandb.errors.UsageError: api_key not configured (no-tty). call wandb login [your_api_key]

2023-11-02 16:33:17 ERROR Traceback (most recent call last):
  File "C:\Users\oltie\AppData\Local\Programs\Python\Python310\lib\site-packages\wandb\cli\cli.py", line 102, in wrapper
    return func(*args, **kwargs)
  File "C:\Users\oltie\AppData\Local\Programs\Python\Python310\lib\site-packages\wandb\cli\cli.py", line 246, in login
    wandb.login(relogin=relogin, key=key, anonymous=anon_mode, host=host, force=True)
  File "C:\Users\oltie\AppData\Local\Programs\Python\Python310\lib\site-packages\wandb\sdk\wandb_login.py", line 77, in login
    configured = _login(**kwargs)
  File "C:\Users\oltie\AppData\Local\Programs\Python\Python310\lib\site-packages\wandb\sdk\wandb_login.py", line 298, in _login
    wlogin.prompt_api_key()
  File "C:\Users\oltie\AppData\Local\Programs\Python\Python310\lib\site-packages\wandb\sdk\wandb_login.py", line 228, in prompt_api_key
    raise UsageError("api_key not configured (no-tty). call " + directive)
wandb.errors.UsageError: api_key not configured (no-tty). call wandb login [your_api_key]

2023-11-02 16:38:35 ERROR Traceback (most recent call last):
  File "C:\Users\oltie\AppData\Local\Programs\Python\Python310\lib\site-packages\wandb\cli\cli.py", line 102, in wrapper
    return func(*args, **kwargs)
  File "C:\Users\oltie\AppData\Local\Programs\Python\Python310\lib\site-packages\wandb\cli\cli.py", line 246, in login
    wandb.login(relogin=relogin, key=key, anonymous=anon_mode, host=host, force=True)
  File "C:\Users\oltie\AppData\Local\Programs\Python\Python310\lib\site-packages\wandb\sdk\wandb_login.py", line 77, in login
    configured = _login(**kwargs)
  File "C:\Users\oltie\AppData\Local\Programs\Python\Python310\lib\site-packages\wandb\sdk\wandb_login.py", line 298, in _login
    wlogin.prompt_api_key()
  File "C:\Users\oltie\AppData\Local\Programs\Python\Python310\lib\site-packages\wandb\sdk\wandb_login.py", line 228, in prompt_api_key
    raise UsageError("api_key not configured (no-tty). call " + directive)
wandb.errors.UsageError: api_key not configured (no-tty). call wandb login [your_api_key]

2023-11-02 16:45:48 ERROR Traceback (most recent call last):
  File "C:\Users\oltie\AppData\Local\Programs\Python\Python310\lib\site-packages\wandb\cli\cli.py", line 102, in wrapper
    return func(*args, **kwargs)
  File "C:\Users\oltie\AppData\Local\Programs\Python\Python310\lib\site-packages\wandb\cli\cli.py", line 246, in login
    wandb.login(relogin=relogin, key=key, anonymous=anon_mode, host=host, force=True)
  File "C:\Users\oltie\AppData\Local\Programs\Python\Python310\lib\site-packages\wandb\sdk\wandb_login.py", line 77, in login
    configured = _login(**kwargs)
  File "C:\Users\oltie\AppData\Local\Programs\Python\Python310\lib\site-packages\wandb\sdk\wandb_login.py", line 298, in _login
    wlogin.prompt_api_key()
  File "C:\Users\oltie\AppData\Local\Programs\Python\Python310\lib\site-packages\wandb\sdk\wandb_login.py", line 228, in prompt_api_key
    raise UsageError("api_key not configured (no-tty). call " + directive)
wandb.errors.UsageError: api_key not configured (no-tty). call wandb login [your_api_key]

2023-11-02 16:47:42 ERROR Traceback (most recent call last):
  File "C:\Users\oltie\AppData\Local\Programs\Python\Python310\lib\site-packages\wandb\cli\cli.py", line 102, in wrapper
    return func(*args, **kwargs)
  File "C:\Users\oltie\AppData\Local\Programs\Python\Python310\lib\site-packages\wandb\cli\cli.py", line 246, in login
    wandb.login(relogin=relogin, key=key, anonymous=anon_mode, host=host, force=True)
  File "C:\Users\oltie\AppData\Local\Programs\Python\Python310\lib\site-packages\wandb\sdk\wandb_login.py", line 77, in login
    configured = _login(**kwargs)
  File "C:\Users\oltie\AppData\Local\Programs\Python\Python310\lib\site-packages\wandb\sdk\wandb_login.py", line 298, in _login
    wlogin.prompt_api_key()
  File "C:\Users\oltie\AppData\Local\Programs\Python\Python310\lib\site-packages\wandb\sdk\wandb_login.py", line 228, in prompt_api_key
    raise UsageError("api_key not configured (no-tty). call " + directive)
wandb.errors.UsageError: api_key not configured (no-tty). call wandb login [your_api_key]

2023-11-02 17:19:16 ERROR Traceback (most recent call last):
  File "C:\Users\oltie\AppData\Local\Programs\Python\Python310\lib\site-packages\wandb\cli\cli.py", line 102, in wrapper
    return func(*args, **kwargs)
  File "C:\Users\oltie\AppData\Local\Programs\Python\Python310\lib\site-packages\wandb\cli\cli.py", line 246, in login
    wandb.login(relogin=relogin, key=key, anonymous=anon_mode, host=host, force=True)
  File "C:\Users\oltie\AppData\Local\Programs\Python\Python310\lib\site-packages\wandb\sdk\wandb_login.py", line 77, in login
    configured = _login(**kwargs)
  File "C:\Users\oltie\AppData\Local\Programs\Python\Python310\lib\site-packages\wandb\sdk\wandb_login.py", line 298, in _login
    wlogin.prompt_api_key()
  File "C:\Users\oltie\AppData\Local\Programs\Python\Python310\lib\site-packages\wandb\sdk\wandb_login.py", line 228, in prompt_api_key
    raise UsageError("api_key not configured (no-tty). call " + directive)
wandb.errors.UsageError: api_key not configured (no-tty). call wandb login [your_api_key]

2023-11-02 17:25:02 ERROR Traceback (most recent call last):
  File "C:\Users\oltie\AppData\Local\Programs\Python\Python310\lib\site-packages\wandb\cli\cli.py", line 102, in wrapper
    return func(*args, **kwargs)
  File "C:\Users\oltie\AppData\Local\Programs\Python\Python310\lib\site-packages\wandb\cli\cli.py", line 246, in login
    wandb.login(relogin=relogin, key=key, anonymous=anon_mode, host=host, force=True)
  File "C:\Users\oltie\AppData\Local\Programs\Python\Python310\lib\site-packages\wandb\sdk\wandb_login.py", line 77, in login
    configured = _login(**kwargs)
  File "C:\Users\oltie\AppData\Local\Programs\Python\Python310\lib\site-packages\wandb\sdk\wandb_login.py", line 298, in _login
    wlogin.prompt_api_key()
  File "C:\Users\oltie\AppData\Local\Programs\Python\Python310\lib\site-packages\wandb\sdk\wandb_login.py", line 228, in prompt_api_key
    raise UsageError("api_key not configured (no-tty). call " + directive)
wandb.errors.UsageError: api_key not configured (no-tty). call wandb login [your_api_key]

2023-11-02 17:27:58 ERROR Traceback (most recent call last):
  File "C:\Users\oltie\AppData\Local\Programs\Python\Python310\lib\site-packages\wandb\cli\cli.py", line 102, in wrapper
    return func(*args, **kwargs)
  File "C:\Users\oltie\AppData\Local\Programs\Python\Python310\lib\site-packages\wandb\cli\cli.py", line 246, in login
    wandb.login(relogin=relogin, key=key, anonymous=anon_mode, host=host, force=True)
  File "C:\Users\oltie\AppData\Local\Programs\Python\Python310\lib\site-packages\wandb\sdk\wandb_login.py", line 77, in login
    configured = _login(**kwargs)
  File "C:\Users\oltie\AppData\Local\Programs\Python\Python310\lib\site-packages\wandb\sdk\wandb_login.py", line 298, in _login
    wlogin.prompt_api_key()
  File "C:\Users\oltie\AppData\Local\Programs\Python\Python310\lib\site-packages\wandb\sdk\wandb_login.py", line 228, in prompt_api_key
    raise UsageError("api_key not configured (no-tty). call " + directive)
wandb.errors.UsageError: api_key not configured (no-tty). call wandb login [your_api_key]

